Workbook
Name Slicer_Booking_Status: #N/A
Name Slicer_Booking_Status1: #N/A
Name Slicer_Route: #N/A
Name Slicer_Route1: #N/A
Name Slicer_Travel_Class: #N/A

Sheet Row data
A1: Booking_ID | B1: Flight_Date | C1: Route | D1: Passenger_Type | E1: Travel_Class | F1: Ticket_Price | G1: Booking_Status
A2: ABK00122 | B2: 45661 | C2: MGQ-HGA | D2: Adult | E2: Economy | G2: Confirmed
A3: ABK00143 | B3: 45761 | C3: MGQ-ADD | D3: Adult | E3: Economy | F3: 235.06 | G3: Completed
A4: ABK00187 | B4: 45836 | C4: MGQ-ADD | D4: Child | E4: Economy | F4: 266.49 | G4: Completed
A5: ABK00033 | B5: 46095 | C5: MGQ-NBO | D5: Adult | E5: Economy | F5: 235.81
A6: ABK00016 | B6: 45949 | C6: MGQ-ADD | D6: Child | E6: Economy | G6: Completed
A7: ABK00083 | B7: 46047 | C7: MGQ-NBO | D7: Adult | E7: Economy | F7: 194.15 | G7: Completed
A8: ABK00248 | B8: 45792 | C8: MGQ-ADD | D8: Senior | E8: Economy | F8: 214.42 | G8: Completed
A9: ABK00036 | B9: 46020 | C9: MGQ-KMU | D9: Adult | E9: Economy | F9: 81.88 | G9: Completed
A10: ABK00080 | B10: 45963 | C10: MGQ-NBO | D10: Adult | E10: Economy | F10: 251.62 | G10: Completed
A11: ABK00254 | B11: 45782 | D11: Adult | E11: Economy | F11: 78.26 | G11: cancelled
A12: ABK00179 | B12: 45852 | C12: MGQ-NBO | D12: Adult | E12: Economy | F12: 194.56 | G12: Completed
A13: ABK00256 | B13: 45968 | C13: MGQ-NBO | D13: Senior | E13: Economy | F13: 244.68 | G13: Confirmed
A14: ABK00044 | B14: 45773 | C14: MGQ-HGA | D14: Adult | E14: Economy | F14: 86.88 | G14: Completed
A15: ABK00168 | B15: 45684 | C15: MGQ-BSA | D15: Adult | E15: Business | F15: 211.82 | G15: Completed
A16: ABK00209 | B16: 46144 | C16: MGQ-HGA | D16: Adult | E16: Economy | F16: 105.01
A17: ABK00214 | B17: 45660 | C17: MGQ-BSA | D17: Adult | E17: Business | F17: 218.33 | G17: Completed
A18: ABK00075 | B18: 46206 | C18: MGQ-HGA | D18: Adult | F18: 95.2 | G18: Completed
A19: ABK00146 | B19: 46166 | C19: MGQ-NBO | D19: Adult | E19: Economy | G19: Completed
A20: ABK00229 | B20: 46087 | C20: MGQ-HGA | D20: Adult | E20: Economy | F20: 109.8 | G20: Confirmed
A21: ABK00070 | B21: 45996 | C21: MGQ-ADD | D21: Senior | E21: Economy | F21: 287.12 | G21: Confirmed
A22: ABK00041 | C22: MGQ-BSA | D22: Adult | E22: Economy | F22: 115.36 | G22: Completed
A23: ABK00081 | B23: 45755 | C23: MGQ-HGA | D23: Senior | E23: Economy | F23: 89.64 | G23: Completed
A24: ABK00076 | B24: 46138 | C24: MGQ-NBO | D24: Child | E24: Economy | F24: 188.64 | G24: Confirmed
B25: 45795 | C25: MGQ-BSA | D25: Adult | E25: Economy | F25: 108.16 | G25: Completed
A26: ABK00257 | B26: 45733 | C26: MGQ-HGA | D26: Adult | E26: Business | F26: 198.57 | G26: Completed
A27: ABK00103 | B27: 45818 | C27: MGQ-KMU | D27: Adult | E27: Economy | G27: Confirmed
A28: ABK00221 | B28: 45925 | C28: MGQ-HGA | D28: Adult | E28: Economy | G28: Cancelled
A29: ABK00026 | B29: 45840 | C29: MGQ-NBO | E29: Economy | F29: 270.95 | G29: Confirmed
A30: ABK00210 | B30: 45758 | C30: MGQ-HGA | D30: Adult | E30: Business | F30: 222.33 | G30: Completed
A31: ABK00005 | B31: 46188 | C31: MGQ-BSA | D31: Adult | E31: Economy | F31: 127.7
A32: ABK00032 | B32: 45974 | C32: MGQ-ADD | D32: Adult | E32: Economy | F32: 254.28 | G32: Cancelled
A33: ABK00206 | B33: 45770 | C33: MGQ-NBO | D33: Adult | E33: Economy | F33: 215.11 | G33: Confirmed
A34: ABK00056 | B34: 45770 | C34: MGQ-HGA | D34: Child | E34: Economy | F34: 87.51 | G34: Confirmed
A35: ABK00289 | B35: 46067 | C35: MGQ-ADD | D35: Adult | E35: Economy | F35: 297.72 | G35: Completed
A36: ABK00029 | B36: 45859 | C36: MGQ-NBO | D36: Adult | E36: Economy | F36: 195.97 | G36: Cancelled
A37: ABK00245 | B37: 45925 | C37: MGQ-KMU | D37: Child | E37: Business | F37: 186.38 | G37: Cancelled
A38: ABK00264 | B38: 46095 | C38: MGQ-NBO | D38: Adult | E38: Economy | F38: 261.37 | G38: Completed
A39: ABK00224 | B39: 45800 | C39: MGQ-BSA | D39: Adult | E39: Economy | F39: 101.11 | G39: Completed
A40: ABK00136 | B40: 45925 | C40: MGQ-KMU | D40: Adult | E40: Economy | F40: 94.35 | G40: Confirmed
...

Sheet clean_data
A1: Booking_ID | B1: Flight_Date | C1: Route | D1: Passenger_Type | E1: Travel_Class | F1: Ticket_Price | G1: Booking_Status | H1: Precenger_type clean | I1: Traval_class clean | J1: Booking_stustus clean | K1: ROUTE_CLEAN | L1: bookin_id clean
A2: ABK00001 | B2: 45783 | C2: MGQ-HGA | D2: Adult | E2: Economy | F2: 116.16 | G2: Completed | H2: =PROPER(D2) -> Adult | I2: =PROPER(E2) -> Economy | J2: =PROPER(G2) -> Completed | K2: =UPPER(C2:C293) -> MGQ-HGA | L2: =TRIM(A2:A293) -> ABK00001
A3: ABK00002 | B3: 45661 | C3: MGQ-NBO | D3: Adult | E3: Economy | F3: 263.77 | G3: Completed | H3: =PROPER(D3) -> Adult | I3: =PROPER(E3) -> Economy | J3: =PROPER(G3) -> Completed | K3: =UPPER(C3:C293) -> MGQ-NBO | L3: =TRIM(A3:A293) -> ABK00002
A4: ABK00003 | B4: 45892 | C4: MGQ-ADD | D4: Adult | E4: Unknown | F4: 274.58 | G4: Confirmed | H4: =PROPER(D4) -> Adult | I4: =PROPER(E4) -> Unknown | J4: =PROPER(G4) -> Confirmed | K4: =UPPER(C4:C294) -> MGQ-ADD | L4: =TRIM(A4:A294) -> ABK00003
A5: ABK00004 | B5: 45962 | C5: MGQ-ADD | D5: Child | E5: Business | F5: 400.49 | G5: Confirmed | H5: =PROPER(D5) -> Child | I5: =PROPER(E5) -> Business | J5: =PROPER(G5) -> Confirmed | K5: =UPPER(C5:C295) -> MGQ-ADD | L5: =TRIM(A5:A295) -> ABK00004
A6: ABK00005 | B6: 46188 | C6: MGQ-BSA | D6: Adult | E6: Economy | F6: 127.7 | G6: Unknown | H6: =PROPER(D6) -> Adult | I6: =PROPER(E6) -> Economy | J6: =PROPER(G6) -> Unknown | K6: =UPPER(C6:C296) -> MGQ-BSA | L6: =TRIM(A6:A296) -> ABK00005
A7: ABK00006 | B7: 45873 | C7: MGQ-BSA | D7: Adult | E7: Economy | F7: 123.12 | G7: Completed | H7: =PROPER(D7) -> Adult | I7: =PROPER(E7) -> Economy | J7: =PROPER(G7) -> Completed | K7: =UPPER(C7:C297) -> MGQ-BSA | L7: =TRIM(A7:A297) -> ABK00006
A8: ABK00008 | B8: 46028 | C8: MGQ-NBO | D8: Adult | E8: Business | F8: 427.82 | G8: Completed | H8: =PROPER(D8) -> Adult | I8: =PROPER(E8) -> Business | J8: =PROPER(G8) -> Completed | K8: =UPPER(C8:C298) -> MGQ-NBO | L8: =TRIM(A8:A298) -> ABK00008
A9: ABK00009 | B9: 45983 | C9: MGQ-KMU | D9: Adult | E9: Unknown | F9: 169.56 | G9: Confirmed | H9: =PROPER(D9) -> Adult | I9: =PROPER(E9) -> Unknown | J9: =PROPER(G9) -> Confirmed | K9: =UPPER(C9:C299) -> MGQ-KMU | L9: =TRIM(A9:A299) -> ABK00009
A10: ABK00010 | B10: 45776 | C10: MGQ-ADD | D10: Child | E10: Economy | F10: 255.81 | G10: Cancelled | H10: =PROPER(D10) -> Child | I10: =PROPER(E10) -> Economy | J10: =PROPER(G10) -> Cancelled | K10: =UPPER(C10:C300) -> MGQ-ADD | L10: =TRIM(A10:A300) -> ABK00010
A11: ABK00011 | B11: 45874 | C11: MGQ-NBO | D11: Adult | E11: Economy | F11: 262.09 | G11: Confirmed | H11: =PROPER(D11) -> Adult | I11: =PROPER(E11) -> Economy | J11: =PROPER(G11) -> Confirmed | K11: =UPPER(C11:C301) -> MGQ-NBO | L11: =TRIM(A11:A301) -> ABK00011
A12: ABK00012 | B12: 45961 | C12: MGQ-BSA | D12: Adult | E12: Economy | F12: 105.72 | G12: Completed | H12: =PROPER(D12) -> Adult | I12: =PROPER(E12) -> Economy | J12: =PROPER(G12) -> Completed | K12: =UPPER(C12:C302) -> MGQ-BSA | L12: =TRIM(A12:A302) -> ABK00012
A13: ABK00013 | B13: 46035 | C13: MGQ-NBO | D13: Adult | E13: Business | F13: 482.08 | G13: Completed | H13: =PROPER(D13) -> Adult | I13: =PROPER(E13) -> Business | J13: =PROPER(G13) -> Completed | K13: =UPPER(C13:C303) -> MGQ-NBO | L13: =TRIM(A13:A303) -> ABK00013
A14: ABK00014 | B14: 45820 | C14: MGQ-NBO | D14: Adult | E14: Business | F14: 418.55 | G14: Completed | H14: =PROPER(D14) -> Adult | I14: =PROPER(E14) -> Business | J14: =PROPER(G14) -> Completed | K14: =UPPER(C14:C304) -> MGQ-NBO | L14: =TRIM(A14:A304) -> ABK00014
... A293: Unknown | B293: 46118 | C293: MGQ-NBO | D293: Adult | E293: Economy | F293: 261.96 | G293: Completed | H293: =PROPER(D293) -> Adult | I293: =PROPER(E293) -> Economy | J293: =PROPER(G293) -> Completed | K293: =UPPER(C293:C583) -> MGQ-NBO | L293: =TRIM(A293:A583) -> Unknown

Sheet pivot tables
A3: Row Labels | B3: Sum of Ticket_Price
A4: MGQ-ADD | B4: 2084.58
A5: MGQ-BSA | B5: 1054.18
A6: MGQ-HGA | B6: 1996.92
A7: MGQ-KMU | B7: 767.98
A8: MGQ-NBO | B8: 7623.49
A9: UNKNOWN | B9: 801.73
A10: Grand Total | B10: 14328.88
A14: Row Labels | B14: Count of bookin_id clean
A15: Cancelled | B15: 8
A16: Completed | B16: 20
A17: Confirmed | B17: 13
A18: Unknown | B18: 4
A19: Grand Total | B19: 45
A23: Sum of Ticket_Price | B23: Column Labels
A24: Row Labels | B24: Adult | C24: Child | D24: Unknown | E24: Grand Total
A25: Business | B25: 11551.9 | C25: 1639.26 | D25: 1137.72 | E25: 14328.88
A26: Grand Total | B26: 11551.9 | C26: 1639.26 | D26: 1137.72 | E26: 14328.88
A31: Booking_stustus clean | B31: (All)
A33: Row Labels | B33: Count of bookin_id clean
A34: 2025 | B34: 38
A35: 2026 | B35: 7
A36: Grand Total | B36: 45
A41: Sum of Ticket_Price | B41: Column Labels
A42: Row Labels | B42: Business | C42: Grand Total
A43: MGQ-ADD | B43: 2084.58 | C43: 2084.58
A44: MGQ-BSA | B44: 1054.18 | C44: 1054.18
A45: MGQ-HGA | B45: 1996.92 | C45: 1996.92
A46: MGQ-KMU | B46: 767.98 | C46: 767.98
A47: MGQ-NBO | B47: 7623.49 | C47: 7623.49
A48: UNKNOWN | B48: 801.73 | C48: 801.73
A49: Grand Total | B49: 14328.88 | C49: 14328.88
A57: KPIS
A58: total revenue | B58: =SUM(clean_data!F2:F293) -> 58112.25
A59: total booking | B59: =COUNTA(clean_data!A2:A293) -> 292
A60: avarge fare | B60: =AVERAGE(clean_data!F2:F293) -> 199.01455
A61: complation booking | B61: =COUNTIF(clean_data!G2:G293, "Completed") -> 159

Sheet analysis
A4: TOTAL_revenue | B4: =SUM(clean_data!F2:F293) -> 58112.25
A5: avarge_ticket_price | B5: =AVERAGE(clean_data!F2:F293) -> 199.01455
A6: total_booking | B6: =COUNT(clean_data!F2:F293) -> 292
A7: minumun price | B7: =MIN(clean_data!F2:F293) -> -7
A8: max_price | B8: =MAX(clean_data!F2:F293) -> 1018
A10: SUMIF (Confirmed Revenue | B10: =SUMIF(clean_data!G:G, "Confirmed", clean_data!F:F) -> 17272.97
A11: AVERAGEIF (Business ) | B11: =AVERAGEIF(clean_data!E:E, "Business", clean_data!F:F) -> 318.41956
A15: AVARGE | B15: 199.01
A17: misiing value total | B17: 115
A18: Flight_Date: | B18: 20
A20: Booking_Status: | B20: 17
A22: route | B22: 16
A24: Booking_ID: | B24: 15
A26: Passenger_Type: | B26: 15
A28: Travel_Class: | B28: 15
A30: Tiket_price | B30: 17

Sheet dashborad
G5: Total revenue | J5: Total booking | M5: Avarge fare | P5: Complation booking
G27: Average Ticket Price by Route & Travel Class

Sheet dashbord2
C6: Total revenue | H6: Total booking | K6: Avarge fare | O6: Complation booking

Sheet finding anad recomandations
C1: PROJECT FINDINGS & RECOMMENDATIONS.
A4: 5 KEY FINDINGS
A5: 1. Top Revenue Driver: Mogadishu-Nairobi (MGQ-NBO) generated the highest revenue at $22,331.80.
A6: 2. Second Highest Route: Mogadishu-Addis Ababa (MGQ-ADD) generated $15,504.33 with the highest average price ($267.32).
A7: 3. High Business Class Yield: Business Class average price is $318.42 vs Economy Class at $178.17
A8: 4. Completed Bookings Rate: 159 out of 292 bookings (54.45%) were completed successfully ($30,899.44)
A9: 5. Cancellations & Missing Data: 30 bookings were cancelled ($5,899.04) and 17 routes lacked destination codes (UNKNOWN).
A12: 3 STRATEGIC RECOMMENDATIONS
A13: 1. Fleet Expansion: Increase flight capacity and frequencies on high-demand routes (MGQ-NBO & MGQ-ADD)
A14: 2. Target Corporate Travelers: Promote Business Class upgrades and loyalty packages to boost higher-margin sales
A15: 3. Minimize Cancellations & Fix Data Entry: Implement automated customer reminders to reduce cancellations and enforce strict data entry validation at ticketing counters
